<?xml version="1.0" ?>
<sdf version="1.5">

<model name="magni_robot">
  <pose>0.0 0.0 0.0 0.0 0.0 0.0</pose>

  <link name="base_footprint"/>

  <link name="base_link">

    <inertial>
      <pose>-0.15 0 0.03 0 0 0</pose>
      <inertia>
        <ixx>0.0595</ixx>
        <ixy>0</ixy>
        <ixz>0</ixz>
        <iyy>0.1508</iyy>
        <iyz>0</iyz>
        <izz>0.1727</izz>
      </inertia>
      <mass>10</mass>
    </inertial>

    <collision name="base_collision">
      <pose>-0.11 0 0.07 0 0 0</pose>
      <geometry>
        <box>
          <size>0.4 0.22  0.195</size>
        </box>
      </geometry>
    </collision>

    <visual name="base_visual">
    <pose>-0.11 0 -0.029 0 0 0</pose>
    <geometry>
      <mesh>
        <uri>model://magni_robot/meshes/magni_body.dae</uri>
        <scale>1 1 1</scale>
      </mesh>
    </geometry>
    </visual>
  </link>


  <link name="imu_link">
    <sensor name="tb3_imu" type="imu">
      <always_on>true</always_on>
      <update_rate>10</update_rate>
      <imu>
      <angular_velocity>
        <x>
          <noise type="gaussian">
          <mean>0.0</mean>
          <stddev>2e-4</stddev>
          </noise>
        </x>
        <y>
          <noise type="gaussian">
          <mean>0.0</mean>
          <stddev>2e-4</stddev>
          </noise>
        </y>
        <z>
          <noise type="gaussian">
          <mean>0.0</mean>
          <stddev>2e-4</stddev>
          </noise>
        </z>
      </angular_velocity>
      <linear_acceleration>
        <x>
          <noise type="gaussian">
          <mean>0.0</mean>
          <stddev>1.7e-2</stddev>
          </noise>
        </x>
        <y>
          <noise type="gaussian">
          <mean>0.0</mean>
          <stddev>1.7e-2</stddev>
          </noise>
        </y>
        <z>
          <noise type="gaussian">
          <mean>0.0</mean>
          <stddev>1.7e-2</stddev>
          </noise>
        </z>
      </linear_acceleration>
      </imu>
      
      <plugin name="imu" filename="libgazebo_ros_imu_sensor.so">
        <ros>
        <remapping>~/out:=imu</remapping>
        </ros>
      </plugin>
    </sensor>
  </link>

  <link name="base_scan">
    <inertial>
      <pose>-0.15 0  0.195 0 0 0</pose>
      <inertia>
        <ixx>0.001</ixx>
        <ixy>0.000</ixy>
        <ixz>0.000</ixz>
        <iyy>0.001</iyy>
        <iyz>0.000</iyz>
        <izz>0.001</izz>
      </inertia>
      <mass>0.114</mass>
    </inertial>

    <collision name="lidar_sensor_collision">
      <pose>-0.15  0  0.195 0 0 0</pose>
      <geometry>
        <cylinder>
          <radius>0.0508</radius>
          <length>0.055</length>
        </cylinder>
      </geometry>
    </collision>

    <visual name="lidar_sensor_visual">
      <pose>-0.162 0 0.195 0 0 0</pose>
      <geometry>
        <cylinder>
          <radius>0.0508</radius>
          <length>0.055</length>
        </cylinder>
      </geometry>
    </visual>

    <sensor name="hls_lfcd_lds" type="ray">
      <visualize>true</visualize>
      <pose>-0.162 0 0.22 0 0 0</pose>
      <update_rate>30</update_rate>
      <ray>
        <scan>
          <horizontal>
            <samples>360</samples>
            <resolution>1.000000</resolution>
            <min_angle>0.000000</min_angle>
            <max_angle>6.28</max_angle>
          </horizontal>
        </scan>
        <range>
          <min>0.120000</min>
          <max>3.5</max>
          <resolution>0.015000</resolution>
        </range>
        <noise>
          <type>gaussian</type>
          <mean>0.0</mean>
          <stddev>0.01</stddev>
        </noise>
      </ray>

      <plugin name="Lidar_gazebo" filename="libgazebo_ros_ray_sensor.so">
        <ros>
          <remapping>~/out:=scan</remapping>
        </ros>
        <output_type>sensor_msgs/LaserScan</output_type>
        <frame_name>base_scan</frame_name>
      </plugin>
    </sensor>
  </link>

  <link name="wheel_left_link">

    <inertial>
      <pose>0 0.155  0 0 0 0</pose>
      <inertia>
        <ixx>0.0090</ixx>
        <ixy>0</ixy>
        <ixz>0</ixz>
        <iyy>0.0090</iyy>
        <iyz>0</iyz>
        <izz>0.0167</izz>
      </inertia>
      <mass>3.34</mass>
    </inertial>

    <collision name="wheel_left_collision">
      <pose>0 0.155 0 1.57 0 0</pose>
      <geometry>
      <cylinder>
      <radius>0.1</radius>
      <length>0.05</length>
      </cylinder>
      </geometry>
      <surface>
        <friction>
          <ode>
            <mu>1</mu>
            <mu2>0.5</mu2>
            <fdir1>0 0 1</fdir1>
            <slip1>0.0</slip1>
            <slip2>0.0</slip2>
          </ode>
        </friction>
        <contact>
          <ode>
            <soft_cfm>0</soft_cfm>
            <soft_erp>0.2</soft_erp>
            <kp>1e+8</kp>
            <kd>1</kd>
            <max_vel>0.01</max_vel>
            <min_depth>0.005</min_depth>
          </ode>
        </contact>
      </surface>
    </collision>

    <visual name="wheel_left_visual">
      <pose>0 0.085 0 0 0 1.57</pose>
      <geometry>
        <mesh>
          <uri>model://magni_robot/meshes/front_wheel.dae</uri>
          <scale>1 1 1</scale>
        </mesh>
      </geometry>
    </visual>
  </link>

  <link name="wheel_right_link">
    <inertial>
      <pose>0 -0.155  0 0 0 0</pose>
      <inertia>
        <ixx>0.0090</ixx>
        <ixy>0</ixy>
        <ixz>0</ixz>
        <iyy>0.0090</iyy>
        <iyz>0</iyz>
        <izz>0.0167</izz>
      </inertia>
      <mass>3.34</mass>
    </inertial>

    <collision name="wheel_right_collision">
      <pose>0.0 -0.155 0 1.57 0 0 </pose>
      <geometry>
      <cylinder>
      <radius>0.1</radius>
      <length>0.05</length>
      </cylinder>
      </geometry>
      <surface>
        <friction>
          <ode>
            <mu>1</mu>
            <mu2>0.5</mu2>
            <fdir1>0 0 1</fdir1>
            <slip1>0.0</slip1>
            <slip2>0.0</slip2>
          </ode>
        </friction>
        <contact>
          <ode>
            <soft_cfm>0</soft_cfm>
            <soft_erp>0.2</soft_erp>
            <kp>1e+8</kp>
            <kd>1</kd>
            <max_vel>0.01</max_vel>
            <min_depth>0.005</min_depth>
          </ode>
        </contact>
      </surface>
    </collision>

    <visual name="wheel_right_visual">
    <pose>0 -0.085 0 0 0 -1.57</pose>
    <geometry>
    <mesh>
    <uri>model://magni_robot/meshes/front_wheel.dae</uri>
    <scale>1 1 1</scale>
    </mesh>
    </geometry>
    </visual>
  </link>

  <link name='caster_right_link'>
    <pose>-0.081 0 -0.004 -1.57 0 0</pose>
    <inertial>
      <mass>0.005</mass>
      <inertia>
        <ixx>0.001</ixx>
        <ixy>0.000</ixy>
        <ixz>0.000</ixz>
        <iyy>0.001</iyy>
        <iyz>0.000</iyz>
        <izz>0.001</izz>
      </inertia>
    </inertial>
    <collision name='collision'>
      <pose>-0.21 0.055 -0.17 0 0 0</pose>
      <geometry>
        <sphere>
          <radius>0.04</radius>
        </sphere>
      </geometry>
      <surface>
        <friction>
          <ode>
            <mu>0</mu>
            <mu2>0</mu2>
            <fdir1>0 0 1</fdir1>
            <slip1>0.0</slip1>
            <slip2>0.0</slip2>
          </ode>
        </friction>
        <contact>
          <ode>
            <soft_cfm>0</soft_cfm>
            <soft_erp>0.2</soft_erp>
            <kp>1e+8</kp>
            <kd>1</kd>
            <max_vel>0.01</max_vel>
            <min_depth>0.001</min_depth>
          </ode>
        </contact>
      </surface>
    </collision>
    
    <visual name ="caster_right_link_visual">
      <pose>-0.19 0.0 -0.17 1.57 3.142 0</pose>
      <geometry>
        <mesh>
          <uri>model://magni_robot/meshes/caster_wheel.dae</uri>
          <scale>1 1 1</scale>
        </mesh>
      </geometry>
    </visual>
  </link>

  <link name='caster_left_link'>
    <pose>-0.081 0 -0.004 -1.57 0 0</pose>
    <inertial>
      <mass>0.005</mass>
      <inertia>
        <ixx>0.001</ixx>
        <ixy>0.000</ixy>
        <ixz>0.000</ixz>
        <iyy>0.001</iyy>
        <iyz>0.000</iyz>
        <izz>0.001</izz>
      </inertia>
    </inertial>
    <collision name='collision'>
      <pose>-0.21 0.055 -0.17 0 0 0</pose>
      <geometry>
        <sphere>
          <radius>0.04</radius>
        </sphere>
      </geometry>
      <surface>
        <friction>
          <ode>
            <mu>0</mu>
            <mu2>0</mu2>
            <fdir1>0 0 1</fdir1>
            <slip1>0.0</slip1>
            <slip2>0.0</slip2>
          </ode>
        </friction>
        <contact>
          <ode>
            <soft_cfm>0</soft_cfm>
            <soft_erp>0.2</soft_erp>
            <kp>1e+8</kp>
            <kd>1</kd>
            <max_vel>0.01</max_vel>
            <min_depth>0.001</min_depth>
          </ode>
        </contact>
      </surface>
    </collision>

    <visual name ="caster_left_link_visual">
      <pose>-0.19 0.0 0.17 1.57 3.142 0</pose>
      <geometry>
        <mesh>
          <uri>model://magni_robot/meshes/caster_wheel.dae</uri>
          <scale>1 1 1</scale>
        </mesh>
      </geometry>
    </visual>
  </link>


  <joint name="base_joint" type="fixed">
    <parent>base_footprint</parent>
    <child>base_link</child>
    <pose>0.0 0.0 0.1 0 0 0</pose>
  </joint>

  <joint name="wheel_left_joint" type="revolute">
    <parent>base_link</parent>
    <child>wheel_left_link</child>
    <pose>0.0 0.163 0 1.57 0 0</pose>
    <axis>
    <xyz>0 0 -1</xyz>
    </axis>
  </joint>

  <joint name="wheel_right_joint" type="revolute">
    <parent>base_link</parent>
    <child>wheel_right_link</child>
    <pose>0.0 -0.04 0 1.57 0 0</pose>
    <axis>
    <xyz>0 0 -1</xyz>
    </axis>
  </joint>



  <joint name='caster_back_left_joint' type='fixed'>
    <parent>base_link</parent>
    <child>caster_left_link</child>
    <pose>0.0 -0 0 -0 0 0</pose>
  </joint>

  <joint name='caster_back_right_joint' type='fixed'>
    <parent>base_link</parent>
    <child>caster_right_link</child>
    <pose>0.0 -0 0 -0 0 0</pose>
  </joint>


  <joint name="imu_joint" type="fixed">
    <parent>base_link</parent>
    <child>imu_link</child>
    <pose>-0.032 0 0.068 0 0 0</pose>
    <axis>
    <xyz>0 0 1</xyz>
    </axis>
  </joint>

  <joint name="lidar_joint" type="fixed">
    <parent>base_link</parent>
    <child>base_scan</child>
    <pose>-0.032 0 0.171 0 0 0</pose>
    <axis>
    <xyz>0 0 1</xyz>
    </axis>
  </joint>

  <plugin name="diff_drive" filename="libgazebo_ros_diff_drive.so">
    <ros> </ros>
    <update_rate>30</update_rate>

    <!-- wheels -->
    <left_joint>wheel_left_joint</left_joint>
    <right_joint>wheel_right_joint</right_joint>

    <!-- kinematics -->
    <wheel_separation>0.24</wheel_separation>
    <wheel_diameter>0.2</wheel_diameter>

    <!-- limits -->
    <max_wheel_torque>20</max_wheel_torque>
    <max_wheel_acceleration>1.0</max_wheel_acceleration>

    <command_topic>cmd_vel</command_topic>

    <!-- output -->
    <publish_odom>true</publish_odom>
    <publish_odom_tf>true</publish_odom_tf>
    <publish_wheel_tf>false</publish_wheel_tf>

    <odometry_topic>odom</odometry_topic>
    <odometry_frame>odom</odometry_frame>
    <robot_base_frame>base_footprint</robot_base_frame>
  </plugin>


  <!-- Camera realsense -->
  <include>
    <name>front_cam</name>
    <uri>model://realsense</uri>
    <pose>0.07  0.0  0.13 0 0 0</pose>
  </include>

  <!-- Intel realsense camera joint-->

  <joint name="front_realsense_joint" type="fixed">
    <child>front_cam::camera_depth_optical_frame</child>
    <parent>base_link</parent>
    <pose>0.07  0  0.13 0 0 0</pose>
    <axis>
      <xyz>0 0 1</xyz>
    </axis>
  </joint> 
    
</model>
</sdf>
